Workbook

Sheet Cover
B2: SURAKKHA Action - DG ECHO 2026/00158/RQ/01/03
B3: FIVDB - Detailed MEAL Plan & Indicator Performance Tracking Table (IPTT)
B4: Local implementing partner under the technical support of Plan International Bangladesh (PIB)
B6: Action title | C6: Strengthening Integrated EiE, Child Protection, Health & GBV Services for Rohingya Refugees and Host Communities in Cox's Bazar, and Scaling up Multi-Hazard Anticipatory Action (SURAKKHA)
B7: Request number | C7: 2026/00158/RQ/01/03
B8: Action period | C8: 1 June 2026 – 31 May 2028 (24 months / 8 quarters)
B9: Consortium lead | C9: Save the Children International (SC)
B10: Technical supervision of FIVDB | C10: Plan International Bangladesh (PIB)
B11: FIVDB scope | C11: Result 1 – Education in Emergencies (Activities 1-7); Result 2 – Child Protection (Activities 1, 3, 4, 5)
B12: Target camps | C12: Camp 1W, Camp 6, Camp 21, Camp 24 (Cox's Bazar)
B13: FIVDB budget | C13: EUR 592,371.41
B15: Contents
B16: • 1. MEAL Framework, RACI, DCP & Reporting (combined: Framework, RACI Matrix, Data Collection Plan, Reporting Schedule)
B17: • 4. M&E Calendar
B18: • 6. CFM Log Template
B19: • 6b. Collective Feedback
B20: • 6c. Target Breakdown (facility & beneficiary targets by sex/disability)
B21: • 7. IPTT (Indicator Performance Tracking Table)
B22: • 8. Activity Tracker (implementation progress by activity)
B23: • 10. Activity Data Log (per-event data entry, Host/FDMN, sex & age, target/discrepancy)
B24: • 11. Distribution Log (per-item distribution data entry, Host/FDMN, sex & age, ODM/PDM, target/discrepancy)
B25: • 12. Dropout Tracker (learners, staff & volunteers by designation, month-wise trend)
B26: • 12b. Attendance Tracker (learner attendance rate by camp, month-wise under quarter)
... B58: A: Activity Tracker (Sheet 8): RAG compares cumulative ACTUAL (auto, from Sheets 10-11) against cumulative PLANNED (FIVDB's own manual quarterly targets) - On Track >=90%, Slightly Behind 70-89%, Behind <70%. It has nothing to do with the IPTT's indicator-level status.

Sheet 1. MEAL-RACI-DCP-Reporting
B2: 1. MEAL Framework, RACI Matrix, Data Collection Plan & Reporting Schedule
B3: FIVDB delivers Result 1 (Education) and Result 2 Activities 1, 3, 4, 5 (Child Protection) under PIB's technical supervision, within SC's consortium-wide MEAL system. This sheet combines four previously separate sections (Framework, RACI, Data Collection Plan, Reporting Schedule) for a single, continuous read.
B5: 1.1 MEAL Objectives
B6: Objective | C6: Reference
B7: Track FIVDB's contribution to Result 1 and Result 2 indicators against agreed targets, disaggregated by sex, age and disability. | C7: Logframe (Annex I), Result 1 & 2 indicators
B8: Ensure quality, safety and protection-sensitivity of education and case-management/PSS services delivered by FIVDB. | C8: CP Minimum Standards in Humanitarian Settings; Plan Safeguarding Framework
B9: Provide accurate, timely, verifiable data to PIB for consolidation into SC's ECHO interim/final reporting. | C9: Narrative Proposal, reporting obligations section
B10: Maintain a functioning, safe, child-friendly complaints and feedback mechanism (CFM) across all FIVDB camps. | C10: Plan/FIVDB CFM SOP
B11: Generate learning that informs adaptive management of FIVDB's activities across the 24-month action. | C11: MEAL Plan, Section 10 (Learning & Adaptive Management)
B13: 1.2 Guiding Principles
B14: Principle | C14: Reference
B15: Do no harm / child safeguarding is non-negotiable in all data collection involving children. | C15: Plan Safeguarding Framework (Updated Risk Assessment Process, 2024)
B16: Participation: communities (adolescents, parents, CESGs, CBCPCs) are consulted on monitoring design, not only as data sources. | C16: CHS Commitment 4 (participation and feedback)
B17: Triangulation: indicators are, where possible, verified through more than one data source. | C17: IPTT & MEAL Workbook, Sheet 7, Verification/QA Step column
B18: Proportionality: MEAL effort is proportionate to FIVDB's budget share and risk profile within the consortium. | C18: FIVDB Detailed Budget (EUR 592,371.41 total)
B19: Data protection: beneficiary data (esp. CP case data) is stored/shared under SC/PIB's data protection protocol. | C19: SC/PIB Data Protection Protocol
B21: 1.3 MEAL Governance Structure
B22: Level | C22: Responsibility | D22: Reference
B23: FIVDB | C23: Field-level data collection, first-line quality checks, case management, CFM Tier 1, monthly indicator tracker updates. | D23: IPTT & MEAL Workbook, Sheets 7-8
B24: PIB (technical supervision) | C24: Technical quality assurance, monthly data-quality spot checks, consolidation of FIVDB data into EiE_PIB / CP_PIB_V2 tabs, CFM Tier 2 (sensitive/safeguarding) escalation point. | D24: Narrative Proposal, technical supervision arrangements
B25: SC (consortium lead) | C25: Consortium-wide MEAL standards, indicator consolidation across all partners, ECHO interim/final reporting, leads mid-term/final evaluation. | D25: Logframe (Annex I), consortium reporting structure
B27: 1.4 RACI Matrix - FIVDB / PIB / SC
B28: R = Responsible A = Accountable C = Consulted I = Informed
B30: Function | C30: FIVDB | D30: PIB | E30: SC (Lead) | F30: Frequency | G30: Reference
B31: Field data collection (attendance, case files, distributions) | C31: R | D31: C | E31: I | F31: Ongoing/daily | G31: IPTT & MEAL Workbook, Sheets 10-11
B32: Data entry & indicator tracker update | C32: R | D32: A | E32: I | F32: Weekly | G32: IPTT & MEAL Workbook, Sheet 7
B33: Data quality spot-checks / verification visits | C33: C | D33: R | E33: A | F33: Monthly | G33: Field Reporting Templates, Template 7
B34: Indicator consolidation (FIVDB/PIB share) | C34: Input | D34: R | E34: A | F34: Monthly | G34: IPTT & MEAL Workbook, Sheet 7
B35: Consortium indicator consolidation (all partners) | C35: I | D35: Input | E35: R | F35: Quarterly | G35: Logframe (Annex I)
B36: Complaints & feedback handling - Tier 1 (non-sensitive) | C36: R | D36: C | E36: I | F36: Ongoing | G36: MEAL Plan, Section 9 (AAP/CFM)
B37: Complaints & feedback handling - Tier 2 (safeguarding/sensitive) | C37: Escalate | D37: R | E37: A | F37: Within 24-48h | G37: Field Reporting Templates, Template 16
B38: Post-distribution monitoring (PDM) | C38: R | D38: C (QC) | E38: I | F38: Per distribution | G38: IPTT & MEAL Workbook, Sheet 11 (ODM/PDM columns)
B39: Case-management supervision | C39: R (case workers) | D39: R (technical) | E39: A (standards) | F39: Weekly/bi-weekly | G39: CP Minimum Standards, 7-step process
B40: Training delivery & pre/post assessment | C40: R | D40: C | E40: I | F40: Per training | G40: Field Reporting Templates, Template 2
B41: Baseline / KAP survey | C41: Input | D41: R | E41: A | F41: Month 1-2 | G41: MEAL Plan, Section 8 (M&E Calendar)
... B45: Safeguarding incident management | C45: R (first response) | D45: A (escalation) | E45: I | F45: Within 24-48h | G45: Field Reporting Templates, Template 16
B47: 1.5 Data Collection Plan - Tools & Methods
B49: Tool | C49: Purpose | D49: Linked indicator(s) | E49: Responsible | F49: Frequency | G49: Reference
B50: Enrolment/attendance registers (CBLF) | C50: Track learner enrolment, attendance, drop-out | D50: R1-I1, R1-I2, R1-I4, SO-I2 | E50: Facilitators | F50: Daily/weekly | G50: IPTT & MEAL Workbook, Sheet 7
B51: Case management database (CPIMS+ or equivalent) | C51: Track CP case ID, planning, services, closure | D51: R2-I1, R2-I2 | E51: Case workers | F51: Per case, continuous | G51: CP Minimum Standards, 7-step process
...

Sheet 4. M&E Calendar
B2: 4. Monitoring & Evaluation Calendar (by month, grouped under quarter)
B3: X = planned activity in that month. Q1 = Jun-Aug 2026 ... Q8 = Mar-May 2028; months are grouped under their quarter. 'Tool Used' cites the actual template/sheet; 'Tool Status' flags where no ready-made instrument exists yet and needs developing. 'Full Process' gives the step-by-step method, Step 1 to last.
B5: Activity | C5: Tool Used | D5: Tool Status | E5: Indicator Reference | F5: Activity Reference | G5: Full Process (Step 1 to last) | H5: Q1 | K5: Q2 | N5: Q3 | Q5: Q4 | T5: Q5 | W5: Q6 | Z5: Q7 | AC5: Q8 | AF5: Notes
H6: 06/2026 | I6: 07/2026 | J6: 08/2026 | K6: 09/2026 | L6: 10/2026 | M6: 11/2026 | N6: 12/2026 | O6: 01/2027 | P6: 02/2027 | Q6: 03/2027 | R6: 04/2027 | S6: 05/2027 | T6: 06/2027 | U6: 07/2027 | V6: 08/2027 | W6: 09/2027 | X6: 10/2027 | Y6: 11/2027 | Z6: 12/2027 | AA6: 01/2028 | AB6: 02/2028 | AC6: 03/2028 | AD6: 04/2028 | AE6: 05/2028
B7: Baseline / KAP survey | C7: Baseline/KAP Survey Questionnaire | D7: Needs development - no ready-made instrument yet in the Field Reporting Templates pack | E7: SO-I1 | F7: INC-6 | G7: Step 1: Design/adapt questionnaire with PIB MEAL. Step 2: Train enumerators. Step 3: Sample households per camp (stratified by sex/age/disability). Step 4: Administer face-to-face (paper or KoBo/ODK). Step 5: Clean and analyse data. Step 6: Share baseline report with PIB. | H7: X | I7: X | J7: X | K7: X | L7: X | M7: X | AF7: Month 1-2 start-up
B8: Monthly indicator tracking | C8: IPTT Data Reporting Form | D8: Needs development - removed from the Field Reporting Templates pack pending redesign (see pack's closing note) | E8: All Sheet 7 indicators | F8: N/A (cross-cutting) | G8: Step 1: Field staff record activity data in source registers. Step 2: MEAL Officer extracts monthly cumulative figures. Step 3: Enter into IPTT Sheet 7 ACTUAL columns. Step 4: Cross-check against Activity Tracker Sheet 8. Step 5: Flag off-track indicators to Project Manager. | H8: X | I8: X | J8: X | K8: X | L8: X | M8: X | N8: X | O8: X | P8: X | Q8: X | R8: X | S8: X | T8: X | U8: X | V8: X | W8: X | X8: X | Y8: X | Z8: X | AA8: X | AB8: X | AC8: X | AD8: X | AE8: X | AF8: Continuous
B9: Quarterly data review (FIVDB-PIB-SC) | C9: IPTT (Sheet 7) + Activity Tracker (Sheet 8) | D9: Exists - this workbook | E9: All indicators | F9: All activities | G9: Step 1: MEAL Officer prepares quarterly extract. Step 2: Joint meeting scheduled with PIB/SC. Step 3: Walk through IPTT % Achieved and Activity Tracker RAG status together. Step 4: Agree corrective actions for off-track items. Step 5: Minute and circulate action points. | H9: X | I9: X | J9: X | K9: X | L9: X | M9: X | N9: X | O9: X | P9: X | Q9: X | R9: X | S9: X | T9: X | U9: X | V9: X | W9: X | X9: X | Y9: X | Z9: X | AA9: X | AB9: X | AC9: X | AD9: X | AE9: X | AF9: Every quarter
B10: Data quality spot-check (PIB) | C10: Data Quality Check / Spot-Check Report | D10: Exists - Field Reporting Templates, Template 7 | E10: All indicators | F10: N/A (cross-cutting) | G10: Step 1: PIB MEAL randomly samples >=10% of source records. Step 2: Verify reported value against source document. Step 3: Record match/discrepancy and root cause. Step 4: Calculate % accuracy. Step 5: Agree corrective action with FIVDB; set follow-up date. | H10: X | I10: X | J10: X | K10: X | L10: X | M10: X | N10: X | O10: X | P10: X | Q10: X | R10: X | S10: X | T10: X | U10: X | V10: X | W10: X | X10: X | Y10: X | Z10: X | AA10: X | AB10: X | AC10: X | AD10: X | AE10: X | AF10: Monthly, reviewed quarterly
B11: Post-distribution monitoring (PDM) | C11: PDM Questionnaire | D11: Needs development - ODM/PDM tracking columns exist (Sheet 11) but no standalone PDM survey instrument yet | E11: SO-I1 | F11: R1A2, R1A3, R2A3 | G11: Step 1: Select random sample of recipients (2-4 weeks post-distribution). Step 2: Contact by phone or in-person. Step 3: Administer PDM questionnaire (quality, appropriateness, safety, satisfaction). Step 4: Record findings in Distribution Log Sheet 11 (PDM Findings). Step 5: Flag issues for follow-up. | H11: X | I11: X | J11: X | K11: X | L11: X | M11: X | N11: X | O11: X | P11: X | Q11: X | R11: X | S11: X | T11: X | U11: X | V11: X | W11: X | X11: X | Y11: X | Z11: X | AA11: X | AB11: X | AC11: X | AD11: X | AE11: X | AF11: Per distribution cycle
B12: Case management supervision & review | C12: CPMS Supervision Checklist | D12: Needs development - referenced against CP Minimum Standards but not yet built as a standalone checklist | E12: R2-I1, R2-I5 | F12: R2A1 | G12: Step 1: PIB technical supervisor reviews case files. Step 2: Individual/group supervision session with case workers. Step 3: Score against CPMS supervision checklist. Step 4: Identify coaching needs. Step 5: Record in supervision log; follow up at next session. | H12: X | I12: X | J12: X | K12: X | L12: X | M12: X | N12: X | O12: X | P12: X | Q12: X | R12: X | S12: X | T12: X | U12: X | V12: X | W12: X | X12: X | Y12: X | Z12: X | AA12: X | AB12: X | AC12: X | AD12: X | AE12: X | AF12: Weekly/bi-weekly
B13: Facility monitoring checklist | C13: Monitoring Visit Checklist | D13: Exists - Field Reporting Templates, Template 5 | E13: R1-I2, R1-I9, R2-I4 | F13: R1A2, R2A3 | G13: Step 1: Joint FIVDB-PIB site visit scheduled. Step 2: Complete the relevant Template 5 section (by visit type). Step 3: Record observations and photographic evidence. Step 4: Complete Monitoring Visit Report (Template 4). Step 5: Share findings and agree action points. | K13: X | L13: X | M13: X | Q13: X | R13: X | S13: X | W13: X | X13: X | Y13: X | AC13: X | AD13: X | AE13: X | AF13: Quarterly
B14: Mid-term review contribution | C14: IPTT extract + case examples | D14: Exists - this workbook + Field Reporting Templates, Template 10 | E14: All indicators | F14: All activities | G14: Step 1: Compile camp-level data from IPTT/Activity Tracker. Step 2: Self-assess progress against targets. Step 3: Compile illustrative case examples (Template 10). Step 4: Submit to PIB/SC ahead of the review. Step 5: Participate in KIIs/FGDs. | Q14: X | R14: X | S14: X | AF14: Month 12
B15: Interim ECHO report data package | C15: IPTT extract | D15: Exists - this workbook | E15: All indicators | F15: All activities | G15: Step 1: MEAL Officer compiles IPTT extract. Step 2: Draft narrative highlights. Step 3: Compile supporting evidence. Step 4: PIB validates. Step 5: Submit to SC. | Q15: X | R15: X | S15: X | AF15: Month 12
B16: Community perception / KAP midline | C16: Community Perception Survey | D16: Needs development - no standalone instrument yet, to mirror the baseline tool once built | E16: SO-I1 | F16: INC-6 | G16: Step 1: Repeat baseline sampling approach. Step 2: Administer same/comparable questionnaire. Step 3: Analyse and compare to baseline. Step 4: Share midline report with PIB. | Q16: X | R16: X | S16: X | AF16: Month 12
B17: Final evaluation contribution | C17: IPTT extract + KII/FGD participation | D17: Exists - this workbook | E17: All indicators | F17: All activities | G17: Step 1: Support SC/PIB-led evaluators with data access. Step 2: Participate in KIIs/FGDs. Step 3: Verify final indicator values. Step 4: Review draft evaluation findings. | AC17: X | AD17: X | AE17: X | AF17: Month 22-24
B18: Endline KAP survey | C18: Baseline/KAP Survey Questionnaire (repeat) | D18: Needs development - same instrument as baseline, once built | E18: SO-I1 | F18: INC-6 | G18: Step 1: Repeat baseline/midline methodology. Step 2: Administer at project close. Step 3: Compare results against baseline and midline. Step 4: Share endline report. | AC18: X | AD18: X | AE18: X | AF18: Month 22-23
B19: Final ECHO report data package | C19: IPTT extract | D19: Exists - this workbook | E19: All indicators | F19: All activities | G19: Step 1: Compile final IPTT extract for the full 24-month period. Step 2: Draft narrative. Step 3: Compile evidence. Step 4: PIB validates. Step 5: Submit to SC. | AC19: X | AD19: X | AE19: X | AF19: Month 24
B20: Sustainability / handover review | C20: Workshop discussion (no fixed instrument) | D20: Not applicable - facilitated discussion, no data-collection tool needed | E20: SO-I1 | F20: CLOSE | G20: Step 1: Joint FIVDB-PIB-SC workshop scheduled. Step 2: Document lessons learned. Step 3: Agree handover/sustainability arrangements for CESGs, CBCPCs, MPCACs, adolescent clubs. Step 4: Circulate handover plan. | AC20: X | AD20: X | AE20: X | AF20: Month 22-24

Sheet 5b. Dashboard
B2: Dashboard - Program, MEAL, Management & Finance Summary
B3: Live summary pulled automatically from the IPTT (Sheet 7), Activity Tracker (Sheet 8), Budget Tracker (Sheet 13), Activity Data Log (Sheet 10) and Distribution Log (Sheet 11). Nothing on this sheet is entered manually - update the current reporting quarter on the IPTT sheet and everything below recalculates.
B5: Current Reporting Quarter | D5: Overall Budget Utilised | F5: Avg. Physical Progress (all activities) | H5: Total Data Log Entries (Sheets 10+11)
B6: ='7. IPTT'!$C$3 -> 1 | D6: =IFERROR('13. Budget Tracker'!AD21/'13. Budget Tracker'!D21,"") -> 0 | F6: =IFERROR(AVERAGE('8. Activity Tracker'!AD7:AD93),"") | H6: =COUNTA('10. Activity Data Log'!$C$7:$C$46)+COUNTA('11. Distribution Log'!$C$7:$C$46) -> 0
B8: ACTION NEEDED - What requires attention right now
B9: Consolidated from every section below, so decision-makers see what needs attention without reading the whole sheet.
B11: Area | E11: Alert | I11: Count
B12: Activities | E12: Sub-activities marked 'Behind' (Sheet 8) | I12: =COUNTIF('8. Activity Tracker'!AE7:AE93,"Behind") -> 0
B13: Indicators | E13: Indicators 'At Risk' (<70% of expected pace, Sheet 7) | I13: =COUNTIFS('7. IPTT'!$W$15:$W$37,"<0.7",'7. IPTT'!$W$15:$W$37,"<>") -> 8
B14: Budget | E14: Lines at Overspend Risk (>110% utilised, Sheet 13c) | I14: =COUNTIF('13c. Budget - Yearly & Total'!$H$6:$H$19,">1.1") -> 0
B15: CFM | E15: Category 5/6 safeguarding/PSEA/fraud/security concerns logged | I15: =SUMPRODUCT(ISNUMBER(SEARCH("5.",'6. CFM Log Template'!$U$7:$U$46))*1)+SUMPRODUCT(ISNUMBER(SEARCH("6.",'6. CFM Log Template'!$U$7:$U$46))*1) -> 0
B16: Data Quality | E16: Activity Data Log rows missing Event Date (breaks the auto-link) | I16: =SUMPRODUCT(('10. Activity Data Log'!$F$7:$F$46="")*('10. Activity Data Log'!$U$7:$U$46>0)) -> 0
B18: For Management - Implementation Status
B19: RAG status distribution across all 75 sub-activities (Activity Tracker, Sheet 8), based on cumulative % Physical Progress vs plan.
B21: On Track | D21: Slightly Behind | F21: Behind | H21: No data yet
B22: =COUNTIF('8. Activity Tracker'!AE7:AE93,"On Track") -> 0 | D22: =COUNTIF('8. Activity Tracker'!AE7:AE93,"Slightly Behind") -> 0 | F22: =COUNTIF('8. Activity Tracker'!AE7:AE93,"Behind") -> 0 | H22: =COUNTIF('8. Activity Tracker'!AE7:AE93,"No data yet") -> 75
B24: 'Behind' activities need management attention - filter the Activity Tracker's RAG Status column (Sheet 8) directly to see which ones.
B26: For MEAL - Indicator Achievement
B27: % of LOP Target Achieved, averaged by Result (IPTT, Sheet 7). Indicator count classified: On Track (>=90% of expected pace), Watch (70-89%), At Risk (<70%).
B29: Result | D29: Avg % of LOP Target Achieved | F29: Indicators On Track | H29: Indicators Watch | J29: Indicators At Risk
B30: Result 1 (Education) | D30: =IFERROR(AVERAGEIF('7. IPTT'!$B$15:$B$37,"Result 1*",'7. IPTT'!$W$15:$W$37),"") -> 0 | F30: =COUNTIFS('7. IPTT'!$B$15:$B$37,"Result 1*",'7. IPTT'!$W$15:$W$37,">=0.9") -> 0 | H30: =COUNTIFS('7. IPTT'!$B$15:$B$37,"Result 1*",'7. IPTT'!$W$15:$W$37,">=0.7",'7. IPTT'!$W$15:$W$37,"<0.9") -> 0 | J30: =COUNTIFS('7. IPTT'!$B$15:$B$37,"Result 1*",'7. IPTT'!$W$15:$W$37,"<0.7") -> 8
B31: Result 2 (Protection) | D31: =IFERROR(AVERAGEIF('7. IPTT'!$B$15:$B$37,"Result 2*",'7. IPTT'!$W$15:$W$37),"") | F31: =COUNTIFS('7. IPTT'!$B$15:$B$37,"Result 2*",'7. IPTT'!$W$15:$W$37,">=0.9") -> 0 | H31: =COUNTIFS('7. IPTT'!$B$15:$B$37,"Result 2*",'7. IPTT'!$W$15:$W$37,">=0.7",'7. IPTT'!$W$15:$W$37,"<0.9") -> 0 | J31: =COUNTIFS('7. IPTT'!$B$15:$B$37,"Result 2*",'7. IPTT'!$W$15:$W$37,"<0.7") -> 0
B32: Specific Objective | D32: =IFERROR(AVERAGEIF('7. IPTT'!$B$15:$B$37,"Specific Objective Indicator*",'7. IPTT'!$W$15:$W$37),"") | F32: =COUNTIFS('7. IPTT'!$B$15:$B$37,"Specific Objective Indicator*",'7. IPTT'!$W$15:$W$37,">=0.9") -> 0 | H32: =COUNTIFS('7. IPTT'!$B$15:$B$37,"Specific Objective Indicator*",'7. IPTT'!$W$15:$W$37,">=0.7",'7. IPTT'!$W$15:$W$37,"<0.9") -> 0 | J32: =COUNTIFS('7. IPTT'!$B$15:$B$37,"Specific Objective Indicator*",'7. IPTT'!$W$15:$W$37,"<0.7") -> 0
B34: Data collection volume (Sheets 10-11) and retention (Sheet 12) are tracked on their own sheets - see Activity Data Log, Distribution Log, and Dropout Tracker directly for full detail.
B36: For Program Staff - This Quarter's Delivery
B37: Focused on what's due this quarter and what needs catching up - planned vs actually logged, current reporting quarter only.
B39: Metric | G39: Value
B40: Sub-activities with a target planned this quarter | G40: =SUMPRODUCT((COLUMN('8. Activity Tracker'!N7:U93)-COLUMN('8. Activity Tracker'!N7)+1=('7. IPTT'!$C$3))*(N('8. Activity Tracker'!N7:U93)>0)) -> 0
B41: Sub-activities marked 'Behind' (need catch-up) | G41: =COUNTIF('8. Activity Tracker'!AE7:AE93,"Behind") -> 0
B42: Events/sessions logged this quarter (Sheet 10) | G42: =COUNTIF('10. Activity Data Log'!$AD$7:$AD$46,"Q"&'7. IPTT'!$C$3) -> 0
B43: Distributions logged this quarter (Sheet 11) | G43: =COUNTIF('11. Distribution Log'!$AI$7:$AI$46,"Q"&'7. IPTT'!$C$3) -> 0
B44: Participants reached this quarter (Sheet 10, Total Participants) | G44: =SUMIF('10. Activity Data Log'!$AD$7:$AD$46,"Q"&'7. IPTT'!$C$3,'10. Activity Data Log'!$U$7:$U$46) -> 0
B45: Recipients reached this quarter (Sheet 11, Total Recipients) | G45: =SUMIF('11. Distribution Log'!$AI$7:$AI$46,"Q"&'7. IPTT'!$C$3,'11. Distribution Log'!$W$7:$W$46) -> 0
B47: For Finance - Budget Utilisation
B48: From the Budget Tracker (Sheet 13). Utilisation = cumulative spend to date / approved budget, per line.
B50: Metric | E50: Value
B51: Total Approved Budget (EUR) | E51: ='13. Budget Tracker'!E21 -> 592371.41
B52: Total Spent to Date (EUR) | E52: =IFERROR('13. Budget Tracker'!AD21/143,"") -> 0
B53: Overall Utilisation % | E53: =IFERROR('13. Budget Tracker'!AD21/'13. Budget Tracker'!D21,"") -> 0
B54: Budget Lines - Underspend Risk | E54: =COUNTIF('13c. Budget - Yearly & Total'!$H$6:$H$19,"<0.7") -> 13
...

Sheet 6. CFM Log Template
B2: 6. Complaints & Feedback Mechanism (CFM) - Individual Feedback Database
B3: Adapted from Save the Children's MPCA Feedback Database Template for FIVDB/SURAKKHA. Records individual pieces of feedback and concerns (hotline, feedback box, one-to-one conversations, face-to-face). For group/collective feedback (community meetings, FGDs, informal debriefs), use Sheet 6b (Collective Feedback) instead. Do NOT record names or descriptive detail for Category 5/6 sensitive concerns (safeguarding, PSEA, fraud, security) - record only the reference number of the formal report filed with the PIB/FIVDB Safeguarding Focal Point. Category 5/6 concerns must be escalated within 24-48 hours per the Safeguarding Framework.
B5: Information about when and by whom the feedback/concern was received or documented | H5: Information about the person who shared feedback/concern and the feedback/concern itself (OPTIONAL - the person may decline to give this information) | Z5: Information about referring, actioning and closing the feedback loop
B6: Unique Number | C6: Date Received (dd/mm/yy) | D6: Name of Staff Who Received/Documented | E6: Position of Staff Member | F6: Contact Details of Staff Member | G6: Channel | H6: Name of Person Sharing Feedback (if known) | I6: Type of Person | J6: Age (if known) | K6: Age Group (auto) | L6: Gender | M6: Vulnerability | N6: Phone Number (if provided) | O6: Camp | P6: Block (if known) | Q6: Address (if applicable) | R6: Theme/Sector | S6: Activity/Project (Activity Code if known) | T6: Description of Feedback (NOT for Category 5/6 - cite report ref# instead) | U6: Category | V6: Sub-Category (Category 5/6 only) | W6: Date of Referral (dd/mm/yy) | X6: Name of Staff Referred To | Y6: Position of Staff Referred To | Z6: Contact of Staff Referred To | AA6: Actions Undertaken to Resolve (NOT for Category 5/6) | AB6: Status | AC6: Date Resolved (dd/mm/yy) | AD6: Days Taken to Resolve (auto) | AE6: Feedback Loop Closed? (communicated back to person) | AF6: Additional Comments
B7: 1 | K7: =IFERROR(IF(J7="","",IF(J7<18,"Child",IF(J7>=18,"Adult","Unknown"))),"") | AD7: =IFERROR(IF(OR(C7="",AC7=""),"",AC7-C7),"")
B8: 2 | K8: =IFERROR(IF(J8="","",IF(J8<18,"Child",IF(J8>=18,"Adult","Unknown"))),"") | AD8: =IFERROR(IF(OR(C8="",AC8=""),"",AC8-C8),"")
B9: 3 | K9: =IFERROR(IF(J9="","",IF(J9<18,"Child",IF(J9>=18,"Adult","Unknown"))),"") | AD9: =IFERROR(IF(OR(C9="",AC9=""),"",AC9-C9),"")
B10: 4 | K10: =IFERROR(IF(J10="","",IF(J10<18,"Child",IF(J10>=18,"Adult","Unknown"))),"") | AD10: =IFERROR(IF(OR(C10="",AC10=""),"",AC10-C10),"")
B11: 5 | K11: =IFERROR(IF(J11="","",IF(J11<18,"Child",IF(J11>=18,"Adult","Unknown"))),"") | AD11: =IFERROR(IF(OR(C11="",AC11=""),"",AC11-C11),"")
B12: 6 | K12: =IFERROR(IF(J12="","",IF(J12<18,"Child",IF(J12>=18,"Adult","Unknown"))),"") | AD12: =IFERROR(IF(OR(C12="",AC12=""),"",AC12-C12),"")
B13: 7 | K13: =IFERROR(IF(J13="","",IF(J13<18,"Child",IF(J13>=18,"Adult","Unknown"))),"") | AD13: =IFERROR(IF(OR(C13="",AC13=""),"",AC13-C13),"")
B14: 8 | K14: =IFERROR(IF(J14="","",IF(J14<18,"Child",IF(J14>=18,"Adult","Unknown"))),"") | AD14: =IFERROR(IF(OR(C14="",AC14=""),"",AC14-C14),"")
B15: 9 | K15: =IFERROR(IF(J15="","",IF(J15<18,"Child",IF(J15>=18,"Adult","Unknown"))),"") | AD15: =IFERROR(IF(OR(C15="",AC15=""),"",AC15-C15),"")
B16: 10 | K16: =IFERROR(IF(J16="","",IF(J16<18,"Child",IF(J16>=18,"Adult","Unknown"))),"") | AD16: =IFERROR(IF(OR(C16="",AC16=""),"",AC16-C16),"")
B17: 11 | K17: =IFERROR(IF(J17="","",IF(J17<18,"Child",IF(J17>=18,"Adult","Unknown"))),"") | AD17: =IFERROR(IF(OR(C17="",AC17=""),"",AC17-C17),"")
B18: 12 | K18: =IFERROR(IF(J18="","",IF(J18<18,"Child",IF(J18>=18,"Adult","Unknown"))),"") | AD18: =IFERROR(IF(OR(C18="",AC18=""),"",AC18-C18),"")
... B46: 40 | K46: =IFERROR(IF(J46="","",IF(J46<18,"Child",IF(J46>=18,"Adult","Unknown"))),"") | AD46: =IFERROR(IF(OR(C46="",AC46=""),"",AC46-C46),"")

Sheet 6b. Collective Feedback
B2: 6b. Complaints & Feedback Mechanism (CFM) - Collective Feedback
B3: Records feedback gathered from a GROUP of adults or children (e.g. community meetings, FGDs) or informal feedback shared by front-line staff (e.g. during a de-brief session) - as distinct from Sheet 6's individual feedback log. This allows FIVDB/PIB to analyse both formal/individual and informal/collective feedback together.
B5: Unique Number | C5: Date (dd/mm/yy) | D5: Name of Staff Who Documented | E5: Position | F5: Method (community meeting/FGD/debrief) | G5: Camp | H5: Group Composition (e.g. CESG, CBCPC, parents) | I5: No. of Participants (M/F/Total) | J5: Theme/Sector | K5: Summary of Feedback/Concerns Raised | L5: Category | M5: Actions Undertaken | N5: Status | O5: Date Resolved (dd/mm/yy) | P5: Feedback Loop Closed? (communicated back to group) | Q5: Additional Comments
B6: 1
B7: 2
B8: 3
B9: 4
B10: 5
B11: 6
B12: 7
B13: 8
B14: 9
B15: 10
B16: 11
B17: 12
... B45: 40

Sheet 6c. Target Breakdown
B2: 6c. Target Breakdown - FIVDB Facility & Beneficiary Targets
B3: Figures cross-validated against the Narrative Proposal (18-Mar-26), the FIVDB Detailed Budget, and Annex 3 (Locations & Integration Mapping). Updated from earlier Annex-2-derived estimates where the Narrative/Budget give more precise, confirmed numbers - see the Comments column and the note at the end of each section. Education and Protection beneficiary totals are counted as unique within each sector separately; the same person may appear in both sectors, so the combined FIVDB total at the bottom is not a de-duplicated headcount across sectors.
B5: A. Education (Result 1) Targets
B6: A.1 Facility / structure targets
B7: Structure | C7: Camp 1W | D7: Camp 6 | E7: Camp 21 | F7: Camp 24 | G7: Total | H7: Reference
B8: Community-Based Learning Facilities (CBLFs) - girls' | C8: 10 | D8: 10 | E8: 7 | F8: 7 | G8: 34 | H8: Narrative Proposal; camp split computed proportionally (2:1 girls:boys ratio applied to Annex 3 camp totals)
B9: Community-Based Learning Facilities (CBLFs) - boys' | C9: 6 | D9: 5 | E9: 3 | F9: 3 | G9: 17 | H9: Narrative Proposal; camp split computed proportionally (2:1 girls:boys ratio applied to Annex 3 camp totals)
B10: CBLFs total (by camp, per Annex 3) | C10: 16 | D10: 15 | E10: 10 | F10: 10 | G10: 51 | H10: Annex 3, PLAN sheet, rows 3-6
B11: Community Education Support Groups (CESGs, ~1 per 2 CBLFs) | C11: 8 | D11: 8 | E11: 5 | F11: 5 | G11: ~26 groups | H11: FIVDB Detailed Budget, R1A5; camp split = CBLFs per camp / 2, rounded
B12: CORRECTED: FIVDB's 51 facilities are all CBLFs (34 girls' + 17 boys'), per the Narrative Proposal. GoLFs (Girls-Only Learning Facilities, secondary level) belong to SC, not FIVDB - the earlier 'GoLF included within the 51' assumption was incorrect and has been removed. Camp-wise girls'/boys' split is NOT independently specified in the Narrative Proposal or Annex 3 - it is computed by applying the confirmed overall 2:1 girls:boys ratio (34:17) to each camp's known total facility count (16/15/10/10), rounded to whole facilities; validate the actual per-camp split with PIB once site allocation is finalised.
B14: A.2 Beneficiary targets - camp-wise (life of project)
B15: Category | C15: Target (Total) | D15: Total Days/Sessions (indicative) | E15: Of whom with disability | F15: Reference / Basis
B16: Learners (11-18 years) - Camp 1W | C16: 384 | D16: 160 | E16: 37 (3% target) | F16: 384 CBLFs 16 x 24 learners/facility; 66.7% female per facility-ratio
B17: Learners (11-18 years) - Camp 6 | C17: 360 | D17: 150 | E17: 34 (3% target) | F17: 15 CBLFs x 24 learners/facility
B18: Learners (11-18 years) - Camp 21 | C18: 240 | D18: 100 | E18: 23 (3% target) | F18: 10 CBLFs x 24 learners/facility
B19: Learners (11-18 years) - Camp 24 | C19: 240 | D19: 100 | E19: 23 (3% target) | F19: 10 CBLFs x 24 learners/facility
B20: Learners (11-18 years) - TOTAL | C20: 1,224 | D20: - | E20: 37 (3% target) | F20: 51 CBLFs x 24 learners/facility, 2 shifts; matches Narrative Proposal & FIVDB Detailed Budget row 65
B21: CESG members (7-8 per group, ~26 groups) | C21: 204 | D21: - | E21: - | F21: FIVDB Detailed Budget, R1A5; camp split not independently specified
B22: Parents / caregivers (1 per enrolled child) | C22: 1,224 | D22: - | E22: - | F22: FIVDB Detailed Budget, R1A5; follows learner enrolment 1:1, so mirrors the camp split above
B23: Teachers / facilitators (refugee + host) | C23: 68 | D23: - | E23: - | F23: Annex 2, EiE_PIB tab; 51 refugee + 17 host, camp split not independently specified
B24: Learners are broken down camp-wise using the direct, defensible relationship confirmed in the Narrative Proposal: each CBLF serves exactly 24 learners (2 shifts) - so Learners per camp = CBLFs per camp (Section A.1) x 24. This gives clean, source-derived numbers (384/360/240/240), not an estimate. The 'Total Days/Sessions' column for camp-level learner rows shows an indicative female sub-count (applying the same 66.7%/33.3% facility-based sex ratio used in A.1) - not an independently confirmed sex split by camp; validate with PIB. CESG members, Parents/caregivers and Teachers do NOT have an independently confirmed camp-wise split in either the Narrative Proposal or FIVDB Detailed Budget - showing the Total only for these rows is more honest than fabricating a camp breakdown; a camp-wise split can be computed once FIVDB confirms actual CESG/teacher deployment per camp.
B26: B. Child Protection (Result 2) Targets
B27: B.1 Facility / structure targets
B28: Structure | C28: Camp 1W | D28: Camp 6 | E28: Camp 21 | F28: Camp 24 | G28: Total | H28: Reference
B29: MPCAC - newly established | C29: 1 | D29: 1 | E29: 1 | F29: 1 | G29: 4 | H29: Narrative Proposal; Detailed Budget R2A3
B30: MPCAC - refurbished | C30: 1 | D30: 0 | E30: 0 | F30: 1 | G30: 2 | H30: Narrative Proposal; Detailed Budget R2A3
B31: MPCAC total facility actions | C31: 2 | D31: 1 | E31: 1 | F31: 2 | G31: 6 | H31: Narrative Proposal; Detailed Budget R2A3
B32: Case Management Offices | C32: 1 | D32: 1 | E32: 1 | F32: 1 | G32: 4 | H32: FIVDB Detailed Budget, R2A1
B33: Community-Based Child Protection Committees (CBCPCs, 2 per camp x 4 camps) | C33: - | D33: - | E33: - | F33: - | G33: 8 | H33: FIVDB Detailed Budget, R2A4
B34: CONFIRMED: MPCAC (4 new + 2 refurbished = 6) matches exactly between the Narrative Proposal and the Detailed Budget. CBCPCs updated to 8 committees (2 per camp x 4 camps, 17 members each = 136 total members) per the Detailed Budget - more precise than the earlier 'indicative 4' estimate.
B36: B.2 Beneficiary targets (life of project)
B37: Category | C37: Female | D37: Male | E37: Total | F37: Of whom with disability | G37: Reference
B38: Children in case management (R2A1) | C38: 160 | D38: 160 | E38: 320 | F38: TBD | G38: FIVDB Detailed Budget, R2A1
B39: Adolescents in PALS sessions (R2A4) | C39: 2,160 | D39: 2,160 | E39: 4,320 | F39: TBD | G39: FIVDB Detailed Budget, R2A4
B40: Parents/Caregivers in PALS sessions (R2A4) | C40: TBD | D40: TBD | E40: 4,320 | F40: - | G40: FIVDB Detailed Budget, R2A4
B41: CBCPC members (2 x 4 camps x 17) | C41: TBD | D41: TBD | E41: 136 | F41: - | G41: FIVDB Detailed Budget, R2A4
B42: Persons receiving Dignity/MHM kits (CP side, R2A3) | C42: 1,814 | D42: - | E42: 1,814 | F42: - | G42: FIVDB Detailed Budget, R2A3
B43: Community Leaders & Volunteers - DRR/Climate training (R2A4) | C43: TBD | D43: TBD | E43: 240 | F43: - | G43: FIVDB Detailed Budget, R2A4
B44: Case management volunteers (2 per camp x 4 camps) | C44: TBD | D44: TBD | E44: 8 | F44: - | G44: FIVDB Detailed Budget, R2A1
B45: CP total (FIVDB, indicative, categories overlap) | C45: - | D45: - | E45: See rows above | F45: -
...

Sheet 6d. Key Milestones
B2: 6d. Key Milestones - FIVDB (SURAKKHA)
B3: Every FIVDB sub-activity with its expected completion window, derived live from the same planned-quarter data used in the Activity Tracker (Sheet 8) - Q1 = Jun-Aug 2026 through Q8 = Mar-May 2028.
B5: Activity Code | C5: Milestone | D5: Expected Month/Year of Completion | E5: Responsible Person
B6: Result 1: Adolescent girls and boys have sustained access to inclusive, quality learning opportunities in safe, protective, community-based learning facilities.
B7: R1A1.1 | C7: Conduct household survey through community volunteers to identify out-of-school and dropout children. | D7: Jun 2026 - May 2027 | E7: Education Officer
B8: R1A1.2 | C8: Conduct technical/disability assessment and screening of identified children (minimum 3% disability target), referring complex cases to Humanity & Inclusion (HI) under FIVDB's MoU. | D8: Jun 2026 - May 2027 | E8: Education Officer
B9: R1A1.3 | C9: Print placement/assessment and disability-screening tools. | D9: Jun 2026 - May 2027 | E9: Education Officer
B10: R1A2.1 | C10: Provide monthly incentives to host-community teacher volunteers. | D10: Jun 2026 - May 2028 | E10: Education Officer
B11: R1A2.2 | C11: Provide monthly incentives to refugee-community teacher volunteers. | D11: Jun 2026 - May 2028 | E11: Education Officer
B12: R1A2.3 | C12: Distribute scholastic material kits (exercise books, ALP books, drawing books, pens, pencils, water bottle, erasers, sharpeners) to enrolled children, 2 shifts per CBLF. | D12: Jun 2026 - May 2027 | E12: Education Officer
B13: R1A2.4 | C13: Distribute one school bag per enrolled child (one-time distribution). | D13: Jun 2026 - Aug 2026 | E13: Education Officer
B14: R1A2.5 | C14: Provide assistive devices and reasonable accommodation for children with disabilities (device cost only; assessment carried out by HI). | D14: Jun 2026 - May 2027 | E14: Education Officer
B15: R1A2.6 | C15: Provide the CBLF minimum package (floor mats, whiteboards, boxes, stationery, cleaning materials). | D15: Jun 2026 - May 2027 | E15: Education Officer
B16: R1A2.7 | C16: Install solar panels, lighting and fire extinguishers at all CBLFs. | D16: Jun 2026 - May 2027 | E16: Education Officer
B17: R1A2.8 | C17: Cover ongoing CBLF maintenance costs. | D17: Jun 2026 - May 2028 | E17: Education Officer
B18: R1A2.9 | C18: Produce and display IEC materials (safeguarding, child protection, PSHEA posters) at all CBLFs. | D18: Jun 2026 - May 2027 | E18: Education Officer
... B38: R1A5.3 | C38: Hold bi-monthly parent/caregiver engagement meetings (1 parent per enrolled child). | D38: Jun 2026 - May 2028 | E38: Education Officer
B39: Result 2: Strengthened, inclusive child protection services prevent and respond to protection risks of girls, boys, women and men affected by the Rohingya crisis.
B40: R2A1.1 | C40: Identify and enhance the capacity of alternative-care family members (foster and kinship) for unaccompanied/separated children (UASC). | D40: Jun 2026 - May 2027 | E40: Technical Coordinator–Protection
B41: R2A1.2 | C41: Provide case-management need-based and emergency support (NFIs) to children/families in active cases. | D41: Jun 2026 - May 2028 | E41: Technical Coordinator–Protection
B42: R2A1.3 | C42: Maintain functioning Case Management Offices (1 per camp). | D42: Jun 2026 - May 2028 | E42: Technical Coordinator–Protection
B43: R2A1.4 | C43: Deliver case management services per the CPMS 7-step process (non-budgetary - covered by CM Officer/volunteer time). | D43: Jun 2026 - May 2028 | E43: Case Management Officer
B44: R2A1.5 | C44: Train para-social workers, volunteers and facilitators on referral pathways. | D44: Jun 2026 - May 2027 | E44: Technical Coordinator–Protection
B45: R2A1.6 | C45: Provide monthly incentives to case-management volunteers (2 per camp, all refugees) for identification and referral. | D45: Jun 2026 - May 2027 | E45: Technical Coordinator–Protection
B46: R2A1.7 | C46: Provide support-material kits (case-worker kits) for case-management service providers. | D46: Jun 2026 - May 2027 | E46: Technical Coordinator–Protection
B47: R2A3.1 | C47: Construct new MPCACs and refurbish existing MPCACs, including running costs. | D47: Jun 2026 - May 2027 | E47: Technical Coordinator–Protection
B48: R2A3.2 | C48: Roll out 'I Support My Friend' (ISMF) at community level, including inception meeting and adolescent training. | D48: Jun 2026 - May 2027 | E48: Technical Coordinator–Protection
B49: R2A3.3 | C49: Deploy MPCAC facilitators (refugee volunteers, host-community volunteers, security guards) to run PSS/awareness sessions. | D49: Jun 2026 - May 2028 | E49: Technical Coordinator–Protection
B50: R2A3.4 | C50: Orient and engage proactive Men and Boys in GBV prevention and response (bi-weekly sessions). | D50: Jun 2026 - May 2028 | E50: Technical Coordinator–Protection
B51: R2A3.5 | C51: Deliver community-led activities on CP and GBV issues (day/event observation). | D51: Jun 2026 - May 2028 | E51: Technical Coordinator–Protection
... B63: R2A5.5 | C63: Hold a project inception workshop with relevant stakeholders at camp level. | D63: Jun 2026 - Aug 2026 | E63: Project Manager

Sheet 6e. Logframe
B2: 6e. Logframe - FIVDB (SURAKKHA)
B3: Matches the structure of Annex 1 (Logframe) submitted separately to PIB - Level / Ref / Performance Indicator / Target / Agency / Agency Target / Indicator Definition / Comments. Ref codes here (e.g. R1.1) are a THIRD numbering system, distinct from the IPTT's indicator codes (R1-I1) and the Activity Tracker's budget codes (R1A1) - see the Cover sheet FAQ for how the three relate.
B5: Level | C5: Ref | D5: Performance Indicator | E5: Target | F5: Agency | G5: Agency Target | H5: Indicator Definition | I5: Comments / Clarifications
B6: Outcome statement | C6: SO | D6: Girls and boys, including the most vulnerable and children with disabilities, have safe and equitable access to quality, inclusive non-formal education and child protection services.
B7: Outcome indicator | C7: SO.1 | D7: % of beneficiaries reporting that humanitarian assistance is delivered in a safe, accessible, accountable and participatory manner | E7: 85% | F7: FIVDB | G7: 85% | H7: Officially approved Logframe (Annex I) target.
B8: Outcome indicator | C8: SO.2 | D8: % targeted girls and boys who are retained in education at the end of the action | E8: 90% | F8: FIVDB | G8: 90% | H8: Denominator = FIVDB's 1,224 enrolled learners.
B9: Output statement | C9: R1 | D9: Adolescent girls and boys have sustained access to inclusive, quality learning opportunities in safe, protective, community-based learning facilities.
B10: Output indicator | C10: R1.1 | D10: Number of targeted girls and boys enrolled in non-formal education services | E10: 1224 | F10: FIVDB | G10: 1224 | I10: 816 girls + 408 boys across 51 CBLFs.
B11: Output indicator | C11: R1.2 | D11: Number of learning spaces established or restored to minimum standards for safe learning | E11: 51 | F11: FIVDB | G11: 51 | I11: 34 girls' + 17 boys' CBLFs across Camps 1W, 6, 21, 24.
B12: Output indicator | C12: R1.3 | D12: Number of teachers provided with teaching aids/materials | E12: 68 | F12: FIVDB | G12: 68 | I12: 51 refugee + 17 host.
B13: Output indicator | C13: R1.4 | D13: Number of girls and boys provided with learning materials | E13: 1224 | F13: FIVDB | G13: 1224 | I13: Same 1,224 learners as R1.1.
B14: Output indicator | C14: R1.5 | D14: Number of teachers/education personnel showing increased knowledge and teaching skills | E14: 68 | F14: FIVDB | G14: 68 | I14: 100% of FIVDB's own teachers targeted.
B15: Output indicator | C15: R1.6 | D15: Number of students, teachers and other education personnel provided with psycho-social support services | E15: 2516 | F15: FIVDB | G15: 2516 | I15: 68 teachers + 1,224 learners + 1,224 parents/caregivers.
B16: Output indicator | C16: R1.7 | D16: Number of teachers and other education personnel showing increased knowledge and skills to address protection needs | E16: 68 | F16: FIVDB | G16: 68 | I16: FIVDB's own teaching cohort.
B17: Output indicator | C17: R1.8 | D17: Number of girls and boys referred to specialised services | E17: 122 | F17: FIVDB | G17: 122 | I17: ~10% of 1,224 enrolled learners (projection).
B18: Output indicator | C18: R1.9 | D18: % educational facilities carrying out environmental and climate friendly activities day-to-day | E18: 65% | F18: FIVDB | G18: 65% | I18: ~33 of FIVDB's 51 CBLFs.
B19: Output statement | C19: R2 | D19: Strengthened, inclusive child protection services prevent and respond to protection risks of girls, boys, women and men affected by the Rohingya crisis (FIVDB: Activities 1, 3, 4, 5).
B20: Output indicator | C20: R2.1 | D20: (MANDATORY) % of children and caregivers whose urgent child protection needs/risks have been addressed | E20: 95% | F20: FIVDB | G20: 95% | I20: 320 children in case management, 4 Case Management Offices.
B21: Output indicator | C21: R2.2 | D21: % of CAAFAG who benefit from appropriate care and services | E21: 80% | F21: FIVDB | G21: 80% | I21: Within FIVDB's caseload.
B22: Output indicator | C22: R2.3 | D22: Average % knowledge increase amongst participants on the protection subject in focus | E22: 80% | F22: FIVDB | G22: 80% | I22: Pre-/post-test knowledge gain.
B23: Output indicator | C23: R2.4 | D23: (MANDATORY) % of persons who receive appropriate PSS reporting improved wellbeing | E23: 80% | F23: FIVDB | G23: 80% | I23: 6 MPCACs (4 new + 2 refurbished), PALS reaching 4,320 + 4,320.
B24: Output indicator | C24: R2.5 | D24: % of caseworkers whose knowledge assessment score is at least 70% | E24: 75% | F24: FIVDB | G24: 75% | I24: Annual Case Worker Capacity Assessment.
B25: Output indicator (reference) | C25: R2.Ref | D25: (MANDATORY) Number of minimum standards for care for survivors achieved | E25: 12 | F25: FIVDB/PLAN | G25: 12 | H25: SC-led overall (Activity 2); FIVDB's role is referral-only. PLAN's own sub-target is 12 (of 31 reviewed); SC's separate target is 16.

Sheet 7. IPTT
B2: 7. Indicator Performance Tracking Table (IPTT) - FIVDB
B3: >>> SET CURRENT REPORTING QUARTER HERE (1-8): | C3: 1 | D3: (everything in this workbook depends on this cell)
B5: Consortium baselines/targets from the Logframe (Annex I). FIVDB's LOP Target = indicative FIVDB contribution derived from Annex 2 (EiE_PIB / CP_PIB_V2). 'Linked Activity/ies' shows the primary (first-listed) Activity Tracker SUB-ACTIVITY code (Sheet 8) whose own Linked Indicator(s) field matches this indicator - auto-computed, single source of truth. Where more than one sub-activity feeds the same indicator, the rest are listed in 'Additional Linked Sub-Activities' immediately to its right, rather than crammed into one cell. TARGET columns are auto-calculated from LOP Target using the phasing assumptions below (blue cells = editable inputs). ACTUAL columns: for 'Number'-unit indicators, ACTUAL is now AUTOMATIC - cumulative sum, by quarter, of every Activity Tracker (Sheet 8) sub-activity ACTUAL total whose Linked Indicator(s) matches this indicator's code (light-blue cells; no manual entry, recalculates as Sheets 10-11 are populated). For '%'-unit indicators, FIVDB enters cumulative-to-date achievement directly into the quarter cell (yellow cells; survey/assessment-based - a percentage cannot be derived from headcount sums). Validate all figures with PIB at inception.
B7: HOW TO READ THIS SHEET - answers to the most common PIB review questions: (1) LOP Target (column O) is always FIVDB's OWN contribution only - never the wider consortium (SC+FIVDB/PLAN) total; the consortium total and the full breakdown behind every composite figure (e.g. 'X teachers + Y learners + Z parents') are always spelled out in the Comments column so every number is traceable, not just asserted. (2) Several '%'-unit LOP Targets across Result 2 look similar (75-95%) because they are the officially approved figures from the same Logframe (Annex I) table, reflecting comparable prior-phase (ECHO HIP 2023) performance baselines across CP/PSS/GBV service lines - not copied from one row to another; each has its own distinct source paragraph in Comments. (3) Result 2 has 5 Activities; FIVDB delivers Activities 1, 3, 4, 5. Activity 2 (adult 18+ GBV case management) is SC-led and explicitly defined in the Narrative Proposal ('Result 2 - Activity 2'), with FIVDB's role limited to referral - this is why it has no FIVDB budget code (R2A2) anywhere in the Activity Tracker. (4) 'Reference' indicator rows (R2-Ref1-3) are led by another consortium agency, shown here for traceability only - FIVDB is not directly accountable for the full consortium figure on those rows. (5) Any Annex number cited in a Comments cell (e.g. Annex 27) refers to an annex of the consortium's DG ECHO Single Form proposal, held by PIB/SC, not a standalone FIVDB document.
B9: ONGOING-delivery phasing (training, referrals, PSS, case management - accrues continuously) - used only for Status calculation below, not shown per-indicator: | O9: 0.05 | P9: 0.15 | Q9: 0.3 | R9: 0.45 | S9: 0.62 | T9: 0.78 | U9: 0.92 | V9: 1
B10: ENROLMENT/ESTABLISHMENT phasing (learners enrolled, facilities/teachers set up - front-loaded, then RETAINED not re-enrolled): | O10: 0.45 | P10: 0.85 | Q10: 0.97 | R10: 1 | S10: 1 | T10: 1 | U10: 1 | V10: 1
B11: RATIONALE for TWO phasing curves, not one: enrolment/establishment-type indicators (learners enrolled, facilities/teachers/kits set up) do NOT grow every quarter - once a learner is enrolled or a CBLF is established, they don't get 're-enrolled' or 're-established' again next quarter; almost all of the growth happens once, early (CBLF opening, initial enrolment drive), then the LOP target is essentially reached and held (minus/plus small dropout replacement, tracked separately in the Dropout Tracker, Sheet 12). Ongoing-delivery indicators (training sessions, referrals, PSS, case management, knowledge assessments) behave differently - they genuinely accrue new instances every quarter as activities continue - so they follow the original S-curve instead. R1-I1, R1-I2, R1-I3 and R1-I4 (enrolment, facilities, teacher/learner materials) use the ENROLMENT/ESTABLISHMENT curve; every other Number-unit indicator uses the ONGOING-delivery curve - edit either blue/orange row directly if FIVDB's actual pattern differs; the Status column recalculates automatically from whichever row it's assigned to.
B13: Result | C13: Indicator Code | D13: Linked Activity/ies (primary sub-activity) | E13: Additional Linked Sub-Activities | F13: Indicator | G13: Reference Source (indicator origin) | H13: Indicator Definition | I13: Measurement Methodology | J13: Disaggregation Required | K13: Baseline | L13: Target Population / Denominator (indicative) | M13: LOP Target (FIVDB) | N13: Unit | O13: ACTUAL (cumulative, by quarter - auto-linked for Number indicators; FIVDB to complete for % indicators) | W13: % of LOP Target Achieved | X13: Status | Y13: Means of Verification | Z13: Source and Method of Data Collection | AA13: Verification / QA Step | AB13: Frequency | AC13: Responsible | AD13: Support Type (how they support) | AE13: Risks / Assumptions | AF13: How to Articulate in Narrative Report | AG13: Comments | AH13: CUMULATIVE SEX/AGE DISAGGREGATION (auto, from Sheets 10-11)
O14: Q1 | P14: Q2 | Q14: Q3 | R14: Q4 | S14: Q5 | T14: Q6 | U14: Q7 | V14: Q8 | AH14: Girls <18 | AI14: Boys <18 | AJ14: Women 18+ | AK14: Men 18+
B15: RESULT 1 - EDUCATION IN EMERGENCIES (FIVDB Activities 1-7)
